{
 "cells": [
  {
   "cell_type": "code",
   "execution_count": null,
   "metadata": {
    "collapsed": true
   },
   "outputs": [
    {
     "name": "stderr",
     "output_type": "stream",
     "text": [
      "ERROR:root:Internal Python error in the inspect module.\nBelow is the traceback from this internal error.\nERROR:root:Internal Python error in the inspect module.\nBelow is the traceback from this internal error.\nERROR:tornado.general:Uncaught exception in ZMQStream callback\nTraceback (most recent call last):\n  File \"<frozen importlib._bootstrap_external>\", line 87, in _path_is_mode_type\n  File \"<frozen importlib._bootstrap_external>\", line 81, in _path_stat\nFileNotFoundError: [WinError 2] Не удается найти указанный файл: 'C:\\\\ProgramData\\\\Anaconda3\\\\lib\\\\site-packages\\\\sympy\\\\__init__.cp37-win_amd64.pyd'\n\nDuring handling of the above exception, another exception occurred:\n\nTraceback (most recent call last):\n  File \"C:\\Lessons\\venv\\lib\\site-packages\\IPython\\core\\interactiveshell.py\", line 2869, in run_code\n    exec(code_obj, self.user_global_ns, self.user_ns)\n  File \"<ipython-input-1-d7fdf45b83a3>\", line 1, in <module>\n    from sympy import *\n  File \"<frozen importlib._bootstrap>\", line 983, in _find_and_load\n  File \"<frozen importlib._bootstrap>\", line 963, in _find_and_load_unlocked\n  File \"<frozen importlib._bootstrap>\", line 906, in _find_spec\n  File \"<frozen importlib._bootstrap_external>\", line 1280, in find_spec\n  File \"<frozen importlib._bootstrap_external>\", line 1252, in _get_spec\n  File \"<frozen importlib._bootstrap_external>\", line 1383, in find_spec\n  File \"<frozen importlib._bootstrap_external>\", line 95, in _path_isfile\n  File \"<frozen importlib._bootstrap_external>\", line 87, in _path_is_mode_type\nKeyboardInterrupt\n\nDuring handling of the above exception, another exception occurred:\n\nTraceback (most recent call last):\n  File \"C:\\Lessons\\venv\\lib\\site-packages\\IPython\\core\\interactiveshell.py\", line 1809, in showtraceback\n    stb = value._render_traceback_()\nAttributeError: 'KeyboardInterrupt' object has no attribute '_render_traceback_'\n\nDuring handling of the above exception, another exception occurred:\n\nTraceback (most recent call last):\n  File \"C:\\Lessons\\venv\\lib\\site-packages\\IPython\\core\\ultratb.py\", line 1132, in get_records\n    return _fixed_getinnerframes(etb, number_of_lines_of_context, tb_offset)\n  File \"C:\\Lessons\\venv\\lib\\site-packages\\IPython\\core\\ultratb.py\", line 313, in wrapped\n    return f(*args, **kwargs)\n  File \"C:\\Lessons\\venv\\lib\\site-packages\\IPython\\core\\ultratb.py\", line 358, in _fixed_getinnerframes\n    records = fix_frame_records_filenames(inspect.getinnerframes(etb, context))\n  File \"C:\\ProgramData\\Anaconda3\\lib\\inspect.py\", line 1495, in getinnerframes\n    frameinfo = (tb.tb_frame,) + getframeinfo(tb, context)\n  File \"C:\\ProgramData\\Anaconda3\\lib\\inspect.py\", line 1453, in getframeinfo\n    filename = getsourcefile(frame) or getfile(frame)\n  File \"C:\\ProgramData\\Anaconda3\\lib\\inspect.py\", line 696, in getsourcefile\n    if getattr(getmodule(object, filename), '__loader__', None) is not None:\n  File \"C:\\ProgramData\\Anaconda3\\lib\\inspect.py\", line 739, in getmodule\n    f = getabsfile(module)\n  File \"C:\\ProgramData\\Anaconda3\\lib\\inspect.py\", line 708, in getabsfile\n    _filename = getsourcefile(object) or getfile(object)\n  File \"C:\\ProgramData\\Anaconda3\\lib\\inspect.py\", line 693, in getsourcefile\n    if os.path.exists(filename):\n  File \"C:\\ProgramData\\Anaconda3\\lib\\genericpath.py\", line 19, in exists\n    os.stat(path)\nKeyboardInterrupt\n\nDuring handling of the above exception, another exception occurred:\n\nTraceback (most recent call last):\n  File \"C:\\Lessons\\venv\\lib\\site-packages\\IPython\\core\\interactiveshell.py\", line 1812, in showtraceback\n    value, tb, tb_offset=tb_offset)\n  File \"C:\\Lessons\\venv\\lib\\site-packages\\IPython\\core\\ultratb.py\", line 1406, in structured_traceback\n    self, etype, value, tb, tb_offset, number_of_lines_of_context)\n  File \"C:\\Lessons\\venv\\lib\\site-packages\\IPython\\core\\ultratb.py\", line 1314, in structured_traceback\n    self, etype, value, tb, tb_offset, number_of_lines_of_context\n  File \"C:\\Lessons\\venv\\lib\\site-packages\\IPython\\core\\ultratb.py\", line 1164, in structured_traceback\n    tb_offset)\n  File \"C:\\Lessons\\venv\\lib\\site-packages\\IPython\\core\\ultratb.py\", line 1108, in format_exception_as_a_whole\n    records = self.get_records(etb, number_of_lines_of_context, tb_offset)\n  File \"C:\\Lessons\\venv\\lib\\site-packages\\IPython\\core\\ultratb.py\", line 1140, in get_records\n    inspect_error()\n  File \"C:\\Lessons\\venv\\lib\\site-packages\\IPython\\core\\ultratb.py\", line 152, in inspect_error\n    error('Internal Python error in the inspect module.\\n'\n  File \"C:\\ProgramData\\Anaconda3\\lib\\logging\\__init__.py\", line 1910, in error\n    root.error(msg, *args, **kwargs)\n  File \"C:\\ProgramData\\Anaconda3\\lib\\logging\\__init__.py\", line 1361, in error\n    self._log(ERROR, msg, args, **kwargs)\n  File \"C:\\ProgramData\\Anaconda3\\lib\\logging\\__init__.py\", line 1468, in _log\n    self.handle(record)\n  File \"C:\\ProgramData\\Anaconda3\\lib\\logging\\__init__.py\", line 1478, in handle\n    self.callHandlers(record)\n  File \"C:\\ProgramData\\Anaconda3\\lib\\logging\\__init__.py\", line 1540, in callHandlers\n    hdlr.handle(record)\n  File \"C:\\ProgramData\\Anaconda3\\lib\\logging\\__init__.py\", line 854, in handle\n    self.emit(record)\n  File \"C:\\ProgramData\\Anaconda3\\lib\\logging\\__init__.py\", line 985, in emit\n    stream.write(msg)\n  File \"C:\\ProgramData\\Anaconda3\\lib\\site-packages\\ipykernel\\iostream.py\", line 400, in write\n    self.pub_thread.schedule(lambda : self._buffer.write(string))\n  File \"C:\\ProgramData\\Anaconda3\\lib\\site-packages\\ipykernel\\iostream.py\", line 203, in schedule\n    self._event_pipe.send(b'')\n  File \"C:\\ProgramData\\Anaconda3\\lib\\site-packages\\zmq\\sugar\\socket.py\", line 392, in send\n    return super(Socket, self).send(data, flags=flags, copy=copy, track=track)\n  File \"zmq/backend/cython/socket.pyx\", line 725, in zmq.backend.cython.socket.Socket.send\n  File \"zmq/backend/cython/socket.pyx\", line 772, in zmq.backend.cython.socket.Socket.send\n  File \"zmq/backend/cython/socket.pyx\", line 242, in zmq.backend.cython.socket._send_copy\n  File \"zmq/backend/cython/checkrc.pxd\", line 12, in zmq.backend.cython.checkrc._check_rc\nKeyboardInterrupt\n\nDuring handling of the above exception, another exception occurred:\n\nTraceback (most recent call last):\n  File \"C:\\Lessons\\venv\\lib\\site-packages\\IPython\\core\\interactiveshell.py\", line 2809, in run_ast_nodes\n    if self.run_code(code, result):\n  File \"C:\\Lessons\\venv\\lib\\site-packages\\IPython\\core\\interactiveshell.py\", line 2886, in run_code\n    self.showtraceback()\n  File \"C:\\Lessons\\venv\\lib\\site-packages\\IPython\\core\\interactiveshell.py\", line 1824, in showtraceback\n    print('\\n' + self.get_exception_only(), file=sys.stderr)\n  File \"C:\\Lessons\\venv\\lib\\site-packages\\IPython\\core\\interactiveshell.py\", line 1769, in get_exception_only\n    msg = traceback.format_exception_only(etype, value)\n  File \"C:\\ProgramData\\Anaconda3\\lib\\traceback.py\", line 136, in format_exception_only\n    return list(TracebackException(etype, value, None).format_exception_only())\n  File \"C:\\ProgramData\\Anaconda3\\lib\\traceback.py\", line 509, in __init__\n    self._load_lines()\n  File \"C:\\ProgramData\\Anaconda3\\lib\\traceback.py\", line 521, in _load_lines\n    self.__context__._load_lines()\n  File \"C:\\ProgramData\\Anaconda3\\lib\\traceback.py\", line 519, in _load_lines\n    frame.line\n  File \"C:\\ProgramData\\Anaconda3\\lib\\traceback.py\", line 281, in line\n    self._line = linecache.getline(self.filename, self.lineno).strip()\n  File \"C:\\ProgramData\\Anaconda3\\lib\\linecache.py\", line 16, in getline\n    lines = getlines(filename, module_globals)\n  File \"C:\\ProgramData\\Anaconda3\\lib\\linecache.py\", line 47, in getlines\n    return updatecache(filename, module_globals)\n  File \"C:\\ProgramData\\Anaconda3\\lib\\linecache.py\", line 136, in updatecache\n    with tokenize.open(fullname) as fp:\n  File \"C:\\ProgramData\\Anaconda3\\lib\\tokenize.py\", line 447, in open\n    buffer = _builtin_open(filename, 'rb')\nKeyboardInterrupt\n\nDuring handling of the above exception, another exception occurred:\n\nTraceback (most recent call last):\n  File \"C:\\Lessons\\venv\\lib\\site-packages\\IPython\\core\\interactiveshell.py\", line 1809, in showtraceback\n    stb = value._render_traceback_()\nAttributeError: 'KeyboardInterrupt' object has no attribute '_render_traceback_'\n\nDuring handling of the above exception, another exception occurred:\n\nTraceback (most recent call last):\n  File \"C:\\Lessons\\venv\\lib\\site-packages\\IPython\\core\\ultratb.py\", line 1132, in get_records\n    return _fixed_getinnerframes(etb, number_of_lines_of_context, tb_offset)\n  File \"C:\\Lessons\\venv\\lib\\site-packages\\IPython\\core\\ultratb.py\", line 313, in wrapped\n    return f(*args, **kwargs)\n  File \"C:\\Lessons\\venv\\lib\\site-packages\\IPython\\core\\ultratb.py\", line 358, in _fixed_getinnerframes\n    records = fix_frame_records_filenames(inspect.getinnerframes(etb, context))\n  File \"C:\\ProgramData\\Anaconda3\\lib\\inspect.py\", line 1495, in getinnerframes\n    frameinfo = (tb.tb_frame,) + getframeinfo(tb, context)\n  File \"C:\\ProgramData\\Anaconda3\\lib\\inspect.py\", line 1453, in getframeinfo\n    filename = getsourcefile(frame) or getfile(frame)\n  File \"C:\\ProgramData\\Anaconda3\\lib\\inspect.py\", line 693, in getsourcefile\n    if os.path.exists(filename):\n  File \"C:\\ProgramData\\Anaconda3\\lib\\genericpath.py\", line 19, in exists\n    os.stat(path)\nKeyboardInterrupt\n\nDuring handling of the above exception, another exception occurred:\n\nTraceback (most recent call last):\n  File \"C:\\Lessons\\venv\\lib\\site-packages\\IPython\\core\\interactiveshell.py\", line 1812, in showtraceback\n    value, tb, tb_offset=tb_offset)\n  File \"C:\\Lessons\\venv\\lib\\site-packages\\IPython\\core\\ultratb.py\", line 1406, in structured_traceback\n    self, etype, value, tb, tb_offset, number_of_lines_of_context)\n  File \"C:\\Lessons\\venv\\lib\\site-packages\\IPython\\core\\ultratb.py\", line 1314, in structured_traceback\n    self, etype, value, tb, tb_offset, number_of_lines_of_context\n  File \"C:\\Lessons\\venv\\lib\\site-packages\\IPython\\core\\ultratb.py\", line 1164, in structured_traceback\n    tb_offset)\n  File \"C:\\Lessons\\venv\\lib\\site-packages\\IPython\\core\\ultratb.py\", line 1108, in format_exception_as_a_whole\n    records = self.get_records(etb, number_of_lines_of_context, tb_offset)\n  File \"C:\\Lessons\\venv\\lib\\site-packages\\IPython\\core\\ultratb.py\", line 1140, in get_records\n    inspect_error()\n  File \"C:\\Lessons\\venv\\lib\\site-packages\\IPython\\core\\ultratb.py\", line 152, in inspect_error\n    error('Internal Python error in the inspect module.\\n'\n  File \"C:\\ProgramData\\Anaconda3\\lib\\logging\\__init__.py\", line 1910, in error\n    root.error(msg, *args, **kwargs)\n  File \"C:\\ProgramData\\Anaconda3\\lib\\logging\\__init__.py\", line 1361, in error\n    self._log(ERROR, msg, args, **kwargs)\n  File \"C:\\ProgramData\\Anaconda3\\lib\\logging\\__init__.py\", line 1468, in _log\n    self.handle(record)\n  File \"C:\\ProgramData\\Anaconda3\\lib\\logging\\__init__.py\", line 1478, in handle\n    self.callHandlers(record)\n  File \"C:\\ProgramData\\Anaconda3\\lib\\logging\\__init__.py\", line 1540, in callHandlers\n    hdlr.handle(record)\n  File \"C:\\ProgramData\\Anaconda3\\lib\\logging\\__init__.py\", line 854, in handle\n    self.emit(record)\n  File \"C:\\ProgramData\\Anaconda3\\lib\\logging\\__init__.py\", line 985, in emit\n    stream.write(msg)\n  File \"C:\\ProgramData\\Anaconda3\\lib\\site-packages\\ipykernel\\iostream.py\", line 400, in write\n    self.pub_thread.schedule(lambda : self._buffer.write(string))\n  File \"C:\\ProgramData\\Anaconda3\\lib\\site-packages\\ipykernel\\iostream.py\", line 203, in schedule\n    self._event_pipe.send(b'')\n  File \"C:\\ProgramData\\Anaconda3\\lib\\site-packages\\zmq\\sugar\\socket.py\", line 392, in send\n    return super(Socket, self).send(data, flags=flags, copy=copy, track=track)\n  File \"zmq/backend/cython/socket.pyx\", line 725, in zmq.backend.cython.socket.Socket.send\n  File \"zmq/backend/cython/socket.pyx\", line 772, in zmq.backend.cython.socket.Socket.send\n  File \"zmq/backend/cython/socket.pyx\", line 242, in zmq.backend.cython.socket._send_copy\n  File \"zmq/backend/cython/checkrc.pxd\", line 12, in zmq.backend.cython.checkrc._check_rc\nKeyboardInterrupt\n\nDuring handling of the above exception, another exception occurred:\n\nTraceback (most recent call last):\n  File \"C:\\ProgramData\\Anaconda3\\lib\\site-packages\\zmq\\eventloop\\zmqstream.py\", line 432, in _run_callback\n    callback(*args, **kwargs)\n  File \"C:\\ProgramData\\Anaconda3\\lib\\site-packages\\tornado\\stack_context.py\", line 300, in null_wrapper\n    return fn(*args, **kwargs)\n  File \"C:\\ProgramData\\Anaconda3\\lib\\site-packages\\ipykernel\\kernelbase.py\", line 283, in dispatcher\n    return self.dispatch_shell(stream, msg)\n  File \"C:\\ProgramData\\Anaconda3\\lib\\site-packages\\ipykernel\\kernelbase.py\", line 233, in dispatch_shell\n    handler(stream, idents, msg)\n  File \"C:\\ProgramData\\Anaconda3\\lib\\site-packages\\ipykernel\\kernelbase.py\", line 399, in execute_request\n    user_expressions, allow_stdin)\n  File \"C:\\ProgramData\\Anaconda3\\lib\\site-packages\\ipykernel\\ipkernel.py\", line 208, in do_execute\n    res = shell.run_cell(code, store_history=store_history, silent=silent)\n  File \"C:\\ProgramData\\Anaconda3\\lib\\site-packages\\ipykernel\\zmqshell.py\", line 537, in run_cell\n    return super(ZMQInteractiveShell, self).run_cell(*args, **kwargs)\n  File \"C:\\Lessons\\venv\\lib\\site-packages\\IPython\\core\\interactiveshell.py\", line 2705, in run_cell\n    interactivity=interactivity, compiler=compiler, result=result)\n  File \"C:\\Lessons\\venv\\lib\\site-packages\\IPython\\core\\interactiveshell.py\", line 2834, in run_ast_nodes\n    self.showtraceback()\n  File \"C:\\Lessons\\venv\\lib\\site-packages\\IPython\\core\\interactiveshell.py\", line 1824, in showtraceback\n    print('\\n' + self.get_exception_only(), file=sys.stderr)\n  File \"C:\\Lessons\\venv\\lib\\site-packages\\IPython\\core\\interactiveshell.py\", line 1769, in get_exception_only\n    msg = traceback.format_exception_only(etype, value)\n  File \"C:\\ProgramData\\Anaconda3\\lib\\traceback.py\", line 136, in format_exception_only\n    return list(TracebackException(etype, value, None).format_exception_only())\n  File \"C:\\ProgramData\\Anaconda3\\lib\\traceback.py\", line 485, in __init__\n    _seen=_seen)\n  File \"C:\\ProgramData\\Anaconda3\\lib\\traceback.py\", line 485, in __init__\n    _seen=_seen)\n  File \"C:\\ProgramData\\Anaconda3\\lib\\traceback.py\", line 485, in __init__\n    _seen=_seen)\n  [Previous line repeated 3 more times]\n  File \"C:\\ProgramData\\Anaconda3\\lib\\traceback.py\", line 496, in __init__\n    capture_locals=capture_locals)\n  File \"C:\\ProgramData\\Anaconda3\\lib\\traceback.py\", line 353, in extract\n    linecache.checkcache(filename)\n  File \"C:\\Lessons\\venv\\lib\\site-packages\\IPython\\core\\compilerop.py\", line 141, in check_linecache_ipython\n    linecache._checkcache_ori(*args)\n  File \"C:\\ProgramData\\Anaconda3\\lib\\linecache.py\", line 74, in checkcache\n    stat = os.stat(fullname)\nKeyboardInterrupt\n"
     ]
    }
   ],
   "source": [
    "from sympy import *\n",
    "init_printing()\n",
    "x, y = symbols('x, y')\n",
    "y = x**2 + x*2\n",
    "factor(y)"
   ]
  },
  {
   "cell_type": "code",
   "execution_count": null,
   "metadata": {},
   "outputs": [],
   "source": []
  }
 ],
 "metadata": {
  "kernelspec": {
   "display_name": "Python 2",
   "language": "python",
   "name": "python2"
  },
  "language_info": {
   "codemirror_mode": {
    "name": "ipython",
    "version": 2
   },
   "file_extension": ".py",
   "mimetype": "text/x-python",
   "name": "python",
   "nbconvert_exporter": "python",
   "pygments_lexer": "ipython2",
   "version": "2.7.6"
  }
 },
 "nbformat": 4,
 "nbformat_minor": 0
}
